<mujoco model="dg5f_right">
  <compiler angle="radian" meshdir="/home/duplo/git/robohand/src/mujoco_playground/mujoco_playground/_src/manipulation/tesollo_hand/xmls/meshes/tesollo"/>
  <!-- <option cone="elliptic" impratio="10"/> -->

  <option timestep="0.01" integrator="Euler" iterations="5" ls_iterations="8">
    <flag eulerdamp="disable"/>
  </option>

  <custom>
    <numeric data="200" name="max_contact_points"/>
    <!-- <numeric data="12" name="max_geom_pairs"/> -->
  </custom>

  <default>
    <!-- <joint axis="0 1 0" damping=".1"/> -->
    <joint axis="0 1 0" damping="0.2" armature="0.00149376" actuatorfrcrange="-0.2196 0.2196" frictionloss="0.02"/>

    <default class="visual">
      <geom type="mesh" contype="0" conaffinity="0" group="2"/>
    </default>

    <default class="collision">
      <geom group="3" friction="0.2" solref="0.02 1.5" solimp="0.9 0.99 0.001" type="box" mass="0" material="black"/>
      <default class="palm">
        <!-- <geom type="capsule" size="0.012 0.008" pos="0 -0.03 0.015" quat="1 1 0 0" friction="0.7 0.05 0.0002"/> -->
        <geom friction="0.9 0.05 0.0002" rgba=".7 .7 .7 .3"/>
      </default>
      <default class="tip">
        <!-- <geom type="capsule" size="0.012 0.008" pos="0 -0.03 0.015" quat="1 1 0 0" friction="0.7 0.05 0.0002"/> -->
        <geom friction="0.9 0.05 0.0002" rgba=".5 .5 .5 .3"/>
      </default>
    </default>
  </default>

  <asset>
    <material name="black" rgba="0.2 0.2 0.2 1"/>
    <material name="white" rgba="0.9 0.9 0.9 1"/>
    
    <texture type="skybox" builtin="gradient" rgb1="0.3 0.5 0.7" rgb2="0 0 0" width="512" height="3072"/>

    <mesh name="rl_dg_mount_c" content_type="model/stl" file="rl_dg_mount_c_simple.STL"/>
    <mesh name="rl_dg_base_c" content_type="model/stl" file="rl_dg_base_c_simple.STL"/>
    <mesh name="rl_dg_palm_c" content_type="model/stl" file="rl_dg_palm_c.STL"/>
    
    <mesh name="rl_dg_1_1_c" content_type="model/stl" file="rl_dg_1_1_c.STL"/>
    <mesh name="rl_dg_1_2_c" content_type="model/stl" file="rl_dg_1_2_c.STL"/>
    <mesh name="rl_dg_1_3_c" content_type="model/stl" file="rl_dg_1_3_c.STL"/>
    <mesh name="rl_dg_1_4_c" content_type="model/stl" file="rl_dg_1_4_c.STL"/>
    <mesh name="rl_dg_1_tip_c" content_type="model/stl" file="rl_dg_1_tip_c_simple.STL"/>
    
    <mesh name="rl_dg_2_1_c" content_type="model/stl" file="rl_dg_2_1_c.STL"/>
    <mesh name="rl_dg_2_2_c" content_type="model/stl" file="rl_dg_2_2_c.STL"/>
    <mesh name="rl_dg_2_3_c" content_type="model/stl" file="rl_dg_2_3_c.STL"/>
    <mesh name="rl_dg_2_4_c" content_type="model/stl" file="rl_dg_2_4_c.STL"/>
    <mesh name="rl_dg_2_tip_c" content_type="model/stl" file="rl_dg_2_tip_c_simple.STL"/>
    
    <mesh name="rl_dg_3_1_c" content_type="model/stl" file="rl_dg_3_1_c.STL"/>
    <mesh name="rl_dg_3_2_c" content_type="model/stl" file="rl_dg_3_2_c.STL"/>
    <mesh name="rl_dg_3_3_c" content_type="model/stl" file="rl_dg_3_3_c.STL"/>
    <mesh name="rl_dg_3_4_c" content_type="model/stl" file="rl_dg_3_4_c.STL"/>
    <mesh name="rl_dg_3_tip_c" content_type="model/stl" file="rl_dg_2_tip_c_simple.STL"/>
    
    <mesh name="rl_dg_4_1_c" content_type="model/stl" file="rl_dg_4_1_c.STL"/>
    <mesh name="rl_dg_4_2_c" content_type="model/stl" file="rl_dg_4_2_c.STL"/>
    <mesh name="rl_dg_4_3_c" content_type="model/stl" file="rl_dg_4_3_c.STL"/>
    <mesh name="rl_dg_4_4_c" content_type="model/stl" file="rl_dg_4_4_c.STL"/>
    <mesh name="rl_dg_4_tip_c" content_type="model/stl" file="rl_dg_2_tip_c_simple.STL"/>
    
    <mesh name="rl_dg_5_1_c" content_type="model/stl" file="rl_dg_5_1_c.STL"/>
    <mesh name="rl_dg_5_2_c" content_type="model/stl" file="rl_dg_5_2_c.STL"/>
    <mesh name="rl_dg_5_3_c" content_type="model/stl" file="rl_dg_5_3_c.STL"/>
    <mesh name="rl_dg_5_4_c" content_type="model/stl" file="rl_dg_5_4_c.STL"/>
    <mesh name="rl_dg_5_tip_c" content_type="model/stl" file="rl_dg_2_tip_c_simple.STL"/>
  </asset>

  <worldbody>
    <light name="spotlight" mode="targetbodycom" target="palm_lower" pos="3 0 4"/>
    <!-- <light pos="0 0 1"/> -->
    <!-- <light pos="0.3 0 1.5" dir="0 0 -1" directional="true"/> -->
    <!-- <geom name="floor" pos="0 0 -0.1" size="0 0 0.05" type="plane" material="groundplane"/> -->

    <body name="rh" quat="-1 0 -1 0" pos="-0.05 0 0.03">
    <!-- <inertial pos="0.021473 3.1163e-06 0.0028146" quat="0.414969 0.572521 0.572945 0.414433" mass="0.045" diaginertia="1.3718e-05 1.31155e-05 3.31624e-06"/> -->
    <!-- <joint name="rj_wrist_0_1" type="slide" pos="0 0 0" axis="1 0 0" range="-0.3 0.3" actuatorfrcrange="-1.5 1.5" damping="0.01" armature="0.00149376" frictionloss="0.02"/> -->
    <joint name="rj_wrist_0_2" type="slide" pos="0 0 0" axis="0 1 0" range="-0.3 0.3" actuatorfrcrange="-10 10" damping="0.01" armature="0.00149376" frictionloss="0.02"/>
    <joint name="rj_wrist_0_3" type="slide" pos="0 0 0" axis="0 0 1" range="-0.3 0.3" actuatorfrcrange="-10. 10" damping="0.01" armature="0.00149376" frictionloss="0.02"/>
    
    <joint name="rj_wrist_1_1" pos="0 0 0" axis="1 0 0" range="-0.3 0.3" actuatorfrcrange="-1.5 1.5" damping="0.01" armature="0.00149376" frictionloss="0.02"/>
    <joint name="rj_wrist_1_3" pos="0 0 0" axis="0 0 1" range="-0.3 0.3" actuatorfrcrange="-1.5 1.5" damping="0.01" armature="0.00149376" frictionloss="0.02"/>
    
    <body name="mount">
      <inertial pos="0 0 0" quat="0.414969 0.572521 0.572945 0.414433" mass="0.045" diaginertia="1.3718e-05 1.31155e-05 3.31624e-06"/>
      <site name="grasp_site" pos="0.01 0.017 0.02" group="4"/>

      <geom class="visual" type="mesh" mesh="rl_dg_mount_c"/>
      <geom class="visual" pos="0 0 0.004" type="mesh" mesh="rl_dg_base_c"/>
      <geom class="visual" pos="0 0 0.0738" quat="1 0 0 0" type="mesh" mesh="rl_dg_palm_c"/>
      <geom class="palm" size="0.007 0.035 0.015" pos="0.013 0.00 0.135"/>
     
      <geom class="palm" size="0.01 0.014 0.01" pos="0.0135 0.015 0.12" quat="1 0.34 -0.135 0.05"/>

      <geom class="palm" size="0.01 0.018 0.014" pos="0.01195 -0.00923 0.10547" quat="0.99349 0.35827 -0.07395 -0.12441"/>
      <geom class="palm" size="0.0097 0.035 0.014" pos="0.01125 0. 0.13" quat="1 0 -0.13 0"/>
      <geom class="palm" size="0.01 0.0175 0.02" pos="0.01425 -0.0175 0.099" quat="1 0 0 0"/>

      <!-- <geom class="collision" name="base_coll" type="cylinder" size="0.0335 0.035" pos="0.0 0.00 0.037"/> -->

      <body name="palm_lower" pos="0.00 0 0">
        <geom class="palm" size="0.007 0.035 0.02" pos="0.013 0.00 0.1"/>
      </body>
    </body>

    <!-- Thumb -->
    <body name="rl_dg_1_1" pos="-0.0162 0.019 0.0866">
      <inertial pos="0.021473 3.1163e-06 0.0028146" quat="0.414969 0.572521 0.572945 0.414433" mass="0.045" diaginertia="1.3718e-05 1.31155e-05 3.31624e-06"/>
      <joint name="rj_dg_1_1" pos="0 0 0" axis="1 0 0" range="-0.383972 0.890118"/>
      <geom type="mesh" class="visual" mesh="rl_dg_1_1_c"/>
      <geom class="collision" size="0.03 0.011 0.011" pos="0.021473 3.1163e-06 -0.00"/>

      <body name="rl_dg_1_2" pos="0.04195 0 0">
        <inertial pos="0.00055633 0.0155 0.00055633" quat="0.379972 0.152995 -0.59634 0.690357" mass="0.025" diaginertia="2.07162e-06 1.99661e-06 1.37777e-06"/>
        <joint name="rj_dg_1_2" pos="0 0 0" axis="0 0 1" range="-3.14159 0" />
        <geom type="mesh" class="visual" mesh="rl_dg_1_2_c"/>
        <geom class="collision" size="0.011 0.022 0.011" pos="0.00 0.012 -0.00"/>

        <body name="rl_dg_1_3" pos="0 0.031 0">
          <inertial pos="2.3008e-05 0.014842 4.7446e-06" quat="0.523748 0.473568 -0.525398 0.474739" mass="0.045" diaginertia="6.4181e-06 6.01585e-06 2.42154e-06"/>
          <joint name="rj_dg_1_3" pos="0 0 0" axis="1 0 0" range="0 1.5708" />
          <geom type="mesh" class="visual" mesh="rl_dg_1_3_c"/>
          <geom class="collision" size="0.011 0.022 0.0095" pos="2.3008e-05 0.014842 4.7446e-06"/>

          <body name="rl_dg_1_4" pos="0 0.0388 0">
            <inertial pos="-0.000182282 0.0140657 0.000732812" quat="0.521074 0.440882 -0.475371 0.555092" mass="0.05" diaginertia="2.0651e-05 2.02971e-05 3.29812e-06"/>
            <joint name="rj_dg_1_4" pos="0 0 0" axis="1 0 0" range="0 1.5708" />
            <geom type="mesh" class="visual" mesh="rl_dg_1_4_c"/>
            <geom class="collision" size="0.011 0.022 0.0095" pos="2.3008e-05 0.014842 4.7446e-06"/>

            <geom class="visual" pos="0 0.0363 0" quat="1 0 0 0" type="mesh" mesh="rl_dg_1_tip_c" material="white"/>
            <site name="rl_dg_1_tip_c" pos="0 -0.0 0.0" group="4"/>

            <geom name="rl_dg_1_tip" class="tip" size="0.01 0.015 0.009" pos="0 0.0363 0"/>

          </body>
        </body>
      </body>
    </body>

    <!-- Pointer -->
    <body name="rl_dg_2_1" pos="-0.0071 0.027 0.1399">
      <inertial pos="0.001061 0.00024417 0.023499" quat="0.632598 0.317074 0.297256 0.641032" mass="0.045" diaginertia="9.53287e-06 8.0012e-06 5.63792e-06"/>
      <joint name="rj_dg_2_1" pos="0 0 0" axis="1 0 0" range="-0.418879 0.610865" />
      <geom type="mesh" class="visual" mesh="rl_dg_2_1_c"/>
      <geom class="collision" size="0.016 0.011 0.015" pos="0.00 0.0 0.02"/>

      <body name="rl_dg_2_2" pos="0.01765 0 0.0265">
        <inertial pos="-4.7446e-06 2.3008e-05 0.023958" quat="0.998727 0.0504191 0.000239574 0.00141058" mass="0.045" diaginertia="6.4181e-06 6.01585e-06 2.42154e-06"/>
        <joint name="rj_dg_2_2" pos="0 0 0" axis="0 1 0" range="0 2.00713" />
        <geom type="mesh" class="visual" mesh="rl_dg_2_2_c"/>
        <geom class="collision" size="0.0095 0.011 0.022" pos="2.3008e-05 0.0 0.0175"/>

        <body name="rl_dg_2_3" pos="0 0 0.0388">
          <inertial pos="-4.7446e-06 2.3008e-05 0.023958" quat="0.998727 0.0504191 0.000239574 0.00141058" mass="0.045" diaginertia="6.4181e-06 6.01585e-06 2.42154e-06"/>
          <joint name="rj_dg_2_3" pos="0 0 0" axis="0 1 0" range="0 1.5708" />
          <geom type="mesh" class="visual" mesh="rl_dg_2_3_c"/>
          <geom class="collision" size="0.0095 0.011 0.022" pos="2.3008e-05 0.0 0.0175"/>

          <body name="rl_dg_2_4" pos="0 0 0.0388">
            <inertial pos="4.4568e-05 -0.00389127 0.0160588" quat="0.526445 0.843914 -0.0138865 0.10233" mass="0.03" diaginertia="6.58495e-06 5.22897e-06 2.6024e-06"/>
            <joint name="rj_dg_2_4" pos="0 0 0" axis="0 1 0" range="0 1.5708" />
            <geom type="mesh" class="visual" mesh="rl_dg_2_4_c"/>
            <geom class="collision" size="0.0095 0.011 0.013" pos="2.3008e-05 0.0 0.0125"/>

            <geom class="visual" pos="0 0 0.0255" quat="1 0 0 0" type="mesh" mesh="rl_dg_2_tip_c" material="white"/>
            <site name="rl_dg_2_tip_c" pos="0 -0.0 0.0" group="4"/>

            <geom name="rl_dg_2_tip" class="tip" size="0.009 0.009 0.015" pos="0 0 0.0255"/>

          </body>
        </body>
      </body>
    </body>

    <!-- Middle finger -->
    <body name="rl_dg_3_1" pos="-0.0071 0.0025 0.1439">
      <inertial pos="0.0012558 -0.00017703 0.023374" quat="0.648691 0.313074 0.303523 0.623746" mass="0.045" diaginertia="9.33725e-06 7.69718e-06 5.31337e-06"/>
      <joint name="rj_dg_3_1" pos="0 0 0" axis="1 0 0" range="-0.610865 0.610865" />
      <!-- <joint name="rj_dg_3_1" pos="0 0 0" axis="1 0 0" range="-0.1 0.1" /> -->
      <geom type="mesh" class="visual" mesh="rl_dg_3_1_c"/>
      <geom class="collision" size="0.016 0.011 0.015" pos="0.00 0.0 0.02"/>

      <body name="rl_dg_3_2" pos="0.01765 0 0.0265">
        <inertial pos="-4.7446e-06 2.3008e-05 0.023958" quat="0.998727 0.0504191 0.000239574 0.00141058" mass="0.045" diaginertia="6.4181e-06 6.01585e-06 2.42154e-06"/>
        <joint name="rj_dg_3_2" pos="0 0 0" axis="0 1 0" range="0 1.95477" />
        <geom type="mesh" class="visual" mesh="rl_dg_3_2_c"/>
        <geom class="collision" size="0.0095 0.011 0.022" pos="2.3008e-05 0.0 0.0175"/>

        <body name="rl_dg_3_3" pos="0 0 0.0388">
          <inertial pos="-4.7446e-06 2.3008e-05 0.023958" quat="0.998727 0.0504191 0.000239574 0.00141058" mass="0.045" diaginertia="6.4181e-06 6.01585e-06 2.42154e-06"/>
          <joint name="rj_dg_3_3" pos="0 0 0" axis="0 1 0" range="0 1.5708" />
          <geom type="mesh" class="visual" mesh="rl_dg_3_3_c"/>
          <geom class="collision" size="0.0095 0.011 0.022" pos="2.3008e-05 0.0 0.0175"/>

          <body name="rl_dg_3_4" pos="0 0 0.0388">
            <inertial pos="4.4568e-05 -0.00389127 0.0160588" quat="0.526445 0.843914 -0.0138865 0.10233" mass="0.03" diaginertia="6.58495e-06 5.22897e-06 2.6024e-06"/>
            <joint name="rj_dg_3_4" pos="0 0 0" axis="0 1 0" range="0 1.5708" />
            <geom type="mesh" class="visual" mesh="rl_dg_3_4_c"/>
            <geom class="collision" size="0.0095 0.011 0.013" pos="2.3008e-05 0.0 0.0125"/>

            <geom class="visual" pos="0 0 0.0255" quat="1 0 0 0" type="mesh" mesh="rl_dg_3_tip_c" material="white"/>
            <site name="rl_dg_3_tip_c" pos="0 -0.0 0.0" group="4"/>

            <geom name="rl_dg_3_tip" class="tip" size="0.009 0.009 0.015" pos="0 0 0.0255"/>
          </body>
        </body>
      </body>
    </body>

    <!-- Ring finger -->
    <body name="rl_dg_4_1" pos="-0.0071 -0.022 0.1359">
      <inertial pos="6.0566e-05 -0.00058566 0.023499" quat="0.666108 0.307837 0.308411 0.605327" mass="0.045" diaginertia="9.54523e-06 7.99297e-06 5.6344e-06"/>
      <joint name="rj_dg_4_1" pos="0 0 0" axis="1 0 0" range="-0.610865 0.418879" />
      <!-- <joint name="rj_dg_4_1" pos="0 0 0" axis="1 0 0" range="-0.1 0.1" /> -->
      <geom type="mesh" class="visual" mesh="rl_dg_4_1_c"/>
      <geom class="collision" size="0.016 0.011 0.015" pos="0.00 0.0 0.02"/>

      <body name="rl_dg_4_2" pos="0.01765 0 0.0265">
        <inertial pos="-4.7446e-06 2.3008e-05 0.023958" quat="0.998727 0.0504191 0.000239574 0.00141058" mass="0.045" diaginertia="6.4181e-06 6.01585e-06 2.42154e-06"/>
        <joint name="rj_dg_4_2" pos="0 0 0" axis="0 1 0" range="0 1.90241" />
        <geom type="mesh" class="visual" mesh="rl_dg_4_2_c"/>
        <geom class="collision" size="0.0095 0.011 0.022" pos="2.3008e-05 0.0 0.0175"/>

        <body name="rl_dg_4_3" pos="0 0 0.0388">
          <inertial pos="-4.7446e-06 2.3008e-05 0.023958" quat="0.998727 0.0504191 0.000239574 0.00141058" mass="0.045" diaginertia="6.4181e-06 6.01585e-06 2.42154e-06"/>
          <joint name="rj_dg_4_3" pos="0 0 0" axis="0 1 0" range="0 1.5708" />
          <geom type="mesh" class="visual" mesh="rl_dg_4_3_c"/>
          <geom class="collision" size="0.0095 0.011 0.022" pos="2.3008e-05 0.0 0.0175"/>

          <body name="rl_dg_4_4" pos="0 0 0.0388">
            <inertial pos="4.4568e-05 -0.00389127 0.0160588" quat="0.526445 0.843914 -0.0138865 0.10233" mass="0.03" diaginertia="6.58495e-06 5.22897e-06 2.6024e-06"/>
            <joint name="rj_dg_4_4" pos="0 0 0" axis="0 1 0" range="0 1.5708" />
            <geom type="mesh" class="visual" mesh="rl_dg_4_4_c"/>
            <geom class="collision" size="0.0095 0.011 0.013" pos="2.3008e-05 0.0 0.0125"/>

            <geom class="visual" pos="0 0 0.0255" quat="1 0 0 0" type="mesh" mesh="rl_dg_4_tip_c" material="white"/>
            <site name="rl_dg_4_tip_c" pos="0 -0.0 0.0" group="4"/>

            <geom name="rl_dg_4_tip" class="tip" size="0.009 0.009 0.015" pos="0 0 0.0255"/>
          </body>
        </body>
      </body>
    </body>

    <!-- Little finger -->
    <body name="rl_dg_5_1" pos="0.0103 -0.0195 0.092">
      <inertial pos="-0.00433014 -0.0250157 0.0140244" quat="0.856441 0.0940801 -0.138609 0.488309" mass="0.055" diaginertia="2.56498e-05 2.33809e-05 9.54179e-06"/>
      <joint name="rj_dg_5_1" pos="0 0 0" axis="0 0 1" range="-0.0174533 1.0472" />
      <geom type="mesh" class="visual" mesh="rl_dg_5_1_c"/>
      <geom class="collision" size="0.016 0.011 0.015" pos="-0.005 -0.03 0.02"/>
      <geom class="collision" size="0.0075 0.0095 0.005" pos="-0.0 -0.028 0.04"/>

      <body name="rl_dg_5_2" pos="0 -0.028 0.0381">
        <inertial pos="-0.000537631 0.000537631 0.0155001" quat="0.909406 -0.067474 0.162898 0.376687" mass="0.025" diaginertia="2.06912e-06 2.00204e-06 1.37635e-06"/>
        <joint name="rj_dg_5_2" pos="0 0 0" axis="1 0 0" range="-0.418879 0.610865" />
        <!-- <joint name="rj_dg_5_2" pos="0 0 0" axis="1 0 0" range="-0.0 0.610865" /> -->
        <geom type="mesh" class="visual" mesh="rl_dg_5_2_c"/>
        <geom class="collision" size="0.011 0.011 0.011" pos="-0.000537631 0.000537631 0.0155001"/>

        <body name="rl_dg_5_3" pos="0 0 0.031">
          <inertial pos="4.74465e-06 2.30084e-05 0.0148419" quat="0.998727 -0.05042 0.000239567 -0.00141066" mass="0.045" diaginertia="6.41806e-06 6.01584e-06 2.42155e-06"/>
          <joint name="rj_dg_5_3" pos="0 0 0" axis="0 1 0" range="0 1.5708" />
          <geom type="mesh" class="visual" mesh="rl_dg_5_3_c"/>
          <geom class="collision" size="0.0095 0.011 0.022" pos="4.74465e-06 2.30084e-05 0.0148419"/>

          <body name="rl_dg_5_4" pos="0 0 0.0388">
            <inertial pos="5.2052e-05 -0.00381428 0.0176289" quat="0.94731 -0.315963 -0.040746 0.0333238" mass="0.05" diaginertia="1.67134e-05 1.18894e-05 7.53281e-06"/>
            <joint name="rj_dg_5_4" pos="0 0 0" axis="0 1 0" range="0 1.5708" />
            <geom type="mesh" class="visual" mesh="rl_dg_5_4_c"/>
            <geom class="collision" size="0.0095 0.011 0.022" pos="5.2052e-05 0.0 0.0176289"/>

            <geom class="visual" pos="0 0 0.0363" quat="1 0 0 0" type="mesh" mesh="rl_dg_5_tip_c" material="white"/>
            <site name="rl_dg_5_tip_c" pos="0 -0.0 0.0" group="4"/>

            <geom name="rl_dg_5_tip" class="tip" size="0.009 0.009 0.015" pos="0 0 0.0363"/>
          </body>
        </body>
      </body>
    </body>
    </body>

  </worldbody>
  
  <contact>
    <!-- collisions with mount -->
    <exclude body1="mount" body2="rl_dg_1_1"/>
    <exclude body1="mount" body2="rl_dg_2_1"/>
    <exclude body1="mount" body2="rl_dg_3_1"/>
    <exclude body1="mount" body2="rl_dg_4_1"/>
    <exclude body1="mount" body2="rl_dg_5_1"/>

    <exclude body1="mount" body2="rl_dg_1_2"/>
    <exclude body1="mount" body2="rl_dg_2_2"/>
    <exclude body1="mount" body2="rl_dg_3_2"/>
    <exclude body1="mount" body2="rl_dg_4_2"/>
    <exclude body1="mount" body2="rl_dg_5_2"/>

    <exclude body1="mount" body2="rl_dg_1_3"/>
    <exclude body1="mount" body2="rl_dg_2_3"/>
    <exclude body1="mount" body2="rl_dg_3_3"/>
    <exclude body1="mount" body2="rl_dg_4_3"/>
    <exclude body1="mount" body2="rl_dg_5_3"/>

    <exclude body1="palm_lower" body2="rl_dg_1_1"/>
    <exclude body1="palm_lower" body2="rl_dg_1_2"/>
    <exclude body1="palm_lower" body2="rl_dg_1_3"/>

    <!-- collisions with other fingers -->
    <exclude body1="rl_dg_1_1" body2="rl_dg_2_1"/>
    <exclude body1="rl_dg_1_1" body2="rl_dg_3_1"/>
    <exclude body1="rl_dg_1_1" body2="rl_dg_4_1"/>
    <exclude body1="rl_dg_1_1" body2="rl_dg_5_1"/>

    <exclude body1="rl_dg_1_2" body2="rl_dg_2_1"/>
    <exclude body1="rl_dg_1_2" body2="rl_dg_3_1"/>
    <exclude body1="rl_dg_1_2" body2="rl_dg_4_1"/>
    <exclude body1="rl_dg_1_2" body2="rl_dg_5_1"/>

    <exclude body1="rl_dg_5_1" body2="rl_dg_2_1"/>
    <exclude body1="rl_dg_5_1" body2="rl_dg_3_1"/>
    <exclude body1="rl_dg_5_1" body2="rl_dg_4_1"/>

    <exclude body1="rl_dg_5_2" body2="rl_dg_2_1"/>
    <exclude body1="rl_dg_5_2" body2="rl_dg_3_1"/>
    <exclude body1="rl_dg_5_2" body2="rl_dg_4_1"/>

    <exclude body1="rl_dg_3_1" body2="rl_dg_2_1"/>
    <exclude body1="rl_dg_3_1" body2="rl_dg_4_1"/>
    <exclude body1="rl_dg_4_1" body2="rl_dg_2_1"/>
  
    <exclude body1="rl_dg_1_1" body2="rl_dg_1_3"/>
    <exclude body1="rl_dg_1_1" body2="rl_dg_1_4"/>
    <exclude body1="rl_dg_1_2" body2="rl_dg_1_4"/>

    <exclude body1="rl_dg_2_1" body2="rl_dg_2_3"/>
    <exclude body1="rl_dg_2_1" body2="rl_dg_2_4"/>
    <exclude body1="rl_dg_2_2" body2="rl_dg_2_4"/>

    <exclude body1="rl_dg_3_1" body2="rl_dg_3_3"/>
    <exclude body1="rl_dg_3_1" body2="rl_dg_3_4"/>
    <exclude body1="rl_dg_3_2" body2="rl_dg_3_4"/>

    <exclude body1="rl_dg_4_1" body2="rl_dg_4_3"/>
    <exclude body1="rl_dg_4_1" body2="rl_dg_4_4"/>
    <exclude body1="rl_dg_4_2" body2="rl_dg_4_4"/>

    <exclude body1="rl_dg_5_1" body2="rl_dg_5_3"/>
    <exclude body1="rl_dg_5_1" body2="rl_dg_5_4"/>
    <exclude body1="rl_dg_5_2" body2="rl_dg_5_4"/>

  </contact>

  <actuator>
    <!-- <position kp="5" kv="2" name="rj_wrist_0_1_a" joint="rj_wrist_0_1" ctrlrange="-0.3 0.3"/> -->
    <position kp="10" kv="3" name="rj_wrist_0_2_a" joint="rj_wrist_0_2" ctrlrange="-0.3 0.3"/>
    <position kp="10" kv="3" name="rj_wrist_0_3_a" joint="rj_wrist_0_3" ctrlrange="-0.3 0.3"/>

    <position kp="1" kv="0.5" name="rj_wrist_1_1_a" joint="rj_wrist_1_1" ctrlrange="-0.3 0.3"/>
    <position kp="1" kv="0.5" name="rj_wrist_1_3_a" joint="rj_wrist_1_3" ctrlrange="-0.3 0.3"/>

    <position kp="3" name="rj_dg_1_1_a" joint="rj_dg_1_1" ctrlrange="-0.383972 0.890118"/>
    <position kp="3" name="rj_dg_1_2_a" joint="rj_dg_1_2" ctrlrange="-3.14159 0"/>
    <position kp="3" name="rj_dg_1_3_a" joint="rj_dg_1_3" ctrlrange="0 1.5708"/>
    <position kp="3" name="rj_dg_1_4_a" joint="rj_dg_1_4" ctrlrange="0 1.5708"/>

    <position kp="3" name="rj_dg_2_1_a" joint="rj_dg_2_1" ctrlrange="-0.418879 0.610865"/>
    <position kp="3" name="rj_dg_2_2_a" joint="rj_dg_2_2" ctrlrange="0 2.00713"/>
    <position kp="3" name="rj_dg_2_3_a" joint="rj_dg_2_3" ctrlrange="0 1.5708"/>
    <position kp="3" name="rj_dg_2_4_a" joint="rj_dg_2_4" ctrlrange="0 1.5708"/>
 
    <position kp="3" name="rj_dg_3_1_a" joint="rj_dg_3_1" ctrlrange="-0.610865 0.610865"/>
    <position kp="3" name="rj_dg_3_2_a" joint="rj_dg_3_2" ctrlrange="0 1.95477"/>
    <position kp="3" name="rj_dg_3_3_a" joint="rj_dg_3_3" ctrlrange="0 1.5708"/>
    <position kp="3" name="rj_dg_3_4_a" joint="rj_dg_3_4" ctrlrange="0 1.5708"/>

    <position kp="3" name="rj_dg_4_1_a" joint="rj_dg_4_1" ctrlrange="-0.610865 0.418879"/>
    <position kp="3" name="rj_dg_4_2_a" joint="rj_dg_4_2" ctrlrange="0 1.90241"/>
    <position kp="3" name="rj_dg_4_3_a" joint="rj_dg_4_3" ctrlrange="0 1.5708"/>
    <position kp="3" name="rj_dg_4_4_a" joint="rj_dg_4_4" ctrlrange="0 1.5708"/>
 
    <position kp="3" name="rj_dg_5_1_a" joint="rj_dg_5_1" ctrlrange="-0.0174533 1.0472"/>
    <position kp="3" name="rj_dg_5_2_a" joint="rj_dg_5_2" ctrlrange="-0.418879 0.610865"/>
    <position kp="3" name="rj_dg_5_3_a" joint="rj_dg_5_3" ctrlrange="0 1.5708"/>
    <position kp="3" name="rj_dg_5_4_a" joint="rj_dg_5_4" ctrlrange="0 1.5708"/>
  </actuator>
  
</mujoco>
