<mujoco model="masspoint_scene">
  <statistic center="0.15 0 0" extent="0.4" meansize="0.01"/>

  <visual>
    <headlight diffuse=".8 .8 .8" ambient=".2 .2 .2" specular="1 1 1"/>
    <rgba force="1 0 0 1"/>
    <global azimuth="120" elevation="-20"/>
    <map force="0.01" stiffness="500"/>
    <scale forcewidth="0.1" contactwidth="0.5" contactheight="0.2"/>
    <quality shadowsize="8192"/>
  </visual>

  <asset>
    <texture type="skybox" builtin="gradient" rgb1="1 1 1" rgb2="1 1 1" width="800" height="800"/>
    <texture type="2d" name="groundplane" builtin="checker" mark="edge" rgb1="1 1 1" rgb2="1 1 1" markrgb="0 0 0"
      width="300" height="300"/>
    <material name="groundplane" texture="groundplane" texuniform="true" texrepeat="5 5" reflectance="0"/>
  </asset>

  <worldbody>
    <camera name="side" pos="-0.183 0.396 0.296" xyaxes="-0.783 -0.622 -0.000 0.332 -0.419 0.845"/>
    <geom name="floor" pos="0 0 -0.25" size="0 0 0.01" type="plane" material="groundplane" contype="2" conaffinity="2"/>
    <site name="attachment_site" pos="0 0 0" group="4"/>
    
    <body name="goal_1_0" mocap="true" pos="0.2 -0.06 -0.05">
      <geom type="sphere" size=".01" mass=".108" contype="0" conaffinity="0" rgba="1 0 0 0.5"/>
    </body>
    <body name="goal_2_0" mocap="true" pos="0.2 -0.03 -0.05">
      <geom type="sphere" size=".01" mass=".108" contype="0" conaffinity="0" rgba="0 1 0 0.5"/>
    </body>

    <body name="key_0" pos="0.17 0.06 -0.05">
        <inertial pos="0.0 -0.0774 0.0" mass=".01" diaginertia="0.001 0.001 0.001"/>
        <joint name="key_joint_0" pos="0.0 0.0 0.0" axis="0 0 1" type="slide" springref=".5" limited="true" stiffness="0.5" range="-0.024 0.0" damping="1"/>
        <geom pos="0.0 -0.00 0.0" size="0.01 0.01 0.005" type="box"/>
    </body>
    <body name="key_1" pos="0.17 0.03 -0.05">
        <inertial pos="0.0 -0.0774 0.0" mass=".01" diaginertia="0.001 0.001 0.001"/>
        <joint name="key_joint_1" pos="0.0 0.0 0.0" axis="0 0 1" type="slide" springref=".5" limited="true" stiffness="0.5" range="-0.024 0.0" damping="1"/>
        <geom pos="0.0 -0.00 0.0" size="0.01 0.01 0.005" type="box"/>
    </body>
    <body name="key_2" pos="0.17 0.00 -0.05">
        <inertial pos="0.0 -0.0774 0.0" mass=".01" diaginertia="0.001 0.001 0.001"/>
        <joint name="key_joint_2" pos="0.0 0.0 0.0" axis="0 0 1" type="slide" springref=".5" limited="true" stiffness="0.5" range="-0.024 0.0" damping="1"/>
        <geom pos="0.0 -0.00 0.0" size="0.01 0.01 0.005" type="box"/>
    </body>
    <body name="key_3" pos="0.17 -0.03 -0.05">
        <inertial pos="0.0 -0.0774 0.0" mass=".01" diaginertia="0.001 0.001 0.001"/>
        <joint name="key_joint_3" pos="0.0 0.0 0.0" axis="0 0 1" type="slide" springref=".5" limited="true" stiffness="0.5" range="-0.024 0.0" damping="1"/>
        <geom pos="0.0 -0.00 0.0" size="0.01 0.01 0.005" type="box"/>
    </body>
    <body name="key_4" pos="0.17 -0.06 -0.05">
        <inertial pos="0.0 -0.0774 0.0" mass=".01" diaginertia="0.001 0.001 0.001"/>
        <joint name="key_joint_4" pos="0.0 0.0 0.0" axis="0 0 1" type="slide" springref=".5" limited="true" stiffness="0.5" range="-0.024 0.0" damping="1"/>
        <geom pos="0.0 -0.00 0.0" size="0.01 0.01 0.005" type="box"/>
    </body>
    <body name="key_5" pos="0.17 -0.09 -0.05">
        <inertial pos="0.0 -0.0774 0.0" mass=".01" diaginertia="0.001 0.001 0.001"/>
        <joint name="key_joint_5" pos="0.0 0.0 0.0" axis="0 0 1" type="slide" springref=".5" limited="true" stiffness="0.5" range="-0.024 0.0" damping="1"/>
        <geom pos="0.0 -0.00 0.0" size="0.01 0.01 0.005" type="box"/>
    </body>
    <body name="key_6" pos="0.2 0.06 -0.05">
        <inertial pos="0.0 -0.0774 0.0" mass=".01" diaginertia="0.001 0.001 0.001"/>
        <joint name="key_joint_6" pos="0.0 0.0 0.0" axis="0 0 1" type="slide" springref=".5" limited="true" stiffness="0.5" range="-0.024 0.0" damping="1"/>
        <geom pos="0.0 -0.00 0.0" size="0.01 0.01 0.005" type="box"/>
    </body>
    <body name="key_7" pos="0.2 0.03 -0.05">
        <inertial pos="0.0 -0.0774 0.0" mass=".01" diaginertia="0.001 0.001 0.001"/>
        <joint name="key_joint_7" pos="0.0 0.0 0.0" axis="0 0 1" type="slide" springref=".5" limited="true" stiffness="0.5" range="-0.024 0.0" damping="1"/>
        <geom pos="0.0 -0.00 0.0" size="0.01 0.01 0.005" type="box"/>
    </body>

    <body name="key_8" pos="0.2 0.0 -0.05">
        <inertial pos="0.0 -0.0774 0.0" mass=".01" diaginertia="0.001 0.001 0.001"/>
        <joint name="key_joint_8" pos="0.0 0.0 0.0" axis="0 0 1" type="slide" springref=".5" limited="true" stiffness="0.5" range="-0.024 0.0" damping="1"/>
        <geom pos="0.0 -0.00 0.0" size="0.01 0.01 0.005" type="box"/>
    </body>
    <body name="key_9" pos="0.2 -0.03 -0.05">
        <inertial pos="0.0 -0.0774 0.0" mass=".01" diaginertia="0.001 0.001 0.001"/>
        <joint name="key_joint_9" pos="0.0 0.0 0.0" axis="0 0 1" type="slide" springref=".5" limited="true" stiffness="0.5" range="-0.024 0.0" damping="1"/>
        <geom pos="0.0 -0.00 0.0" size="0.01 0.01 0.005" type="box"/>
    </body>


    <body name="key_10" pos="0.2 -0.06 -0.05">
        <inertial pos="0.0 -0.0774 0.0" mass=".01" diaginertia="0.001 0.001 0.001"/>
        <joint name="key_joint_10" pos="0.0 0.0 0.0" axis="0 0 1" type="slide" springref=".5" limited="true" stiffness="0.5" range="-0.024 0.0" damping="1"/>
        <geom pos="0.0 -0.00 0.0" size="0.01 0.01 0.005" type="box"/>
    </body>
    <body name="key_11" pos="0.2 -0.09 -0.05">
        <inertial pos="0.0 -0.0774 0.0" mass=".01" diaginertia="0.001 0.001 0.001"/>
        <joint name="key_joint_11" pos="0.0 0.0 0.0" axis="0 0 1" type="slide" springref=".5" limited="true" stiffness="0.5" range="-0.024 0.0" damping="1"/>
        <geom pos="0.0 -0.00 0.0" size="0.01 0.01 0.005" type="box"/>
    </body>


    <body name="key_12" pos="0.23 0.06 -0.05">
        <inertial pos="0.0 -0.0774 0.0" mass=".01" diaginertia="0.001 0.001 0.001"/>
        <joint name="key_joint_12" pos="0.0 0.0 0.0" axis="0 0 1" type="slide" springref=".5" limited="true" stiffness="0.5" range="-0.024 0.0" damping="1"/>
        <geom pos="0.0 -0.00 0.0" size="0.01 0.01 0.005" type="box"/>
    </body>
    <body name="key_13" pos="0.23 0.03 -0.05">
        <inertial pos="0.0 -0.0774 0.0" mass=".01" diaginertia="0.001 0.001 0.001"/>
        <joint name="key_joint_13" pos="0.0 0.0 0.0" axis="0 0 1" type="slide" springref=".5" limited="true" stiffness="0.5" range="-0.024 0.0" damping="1"/>
        <geom pos="0.0 -0.00 0.0" size="0.01 0.01 0.005" type="box"/>
    </body>
    <body name="key_14" pos="0.23 0.00 -0.05">
        <inertial pos="0.0 -0.0774 0.0" mass=".01" diaginertia="0.001 0.001 0.001"/>
        <joint name="key_joint_14" pos="0.0 0.0 0.0" axis="0 0 1" type="slide" springref=".5" limited="true" stiffness="0.5" range="-0.024 0.0" damping="1"/>
        <geom pos="0.0 -0.00 0.0" size="0.01 0.01 0.005" type="box"/>
    </body>
    <body name="key_15" pos="0.23 -0.03 -0.05">
        <inertial pos="0.0 -0.0774 0.0" mass=".01" diaginertia="0.001 0.001 0.001"/>
        <joint name="key_joint_15" pos="0.0 0.0 0.0" axis="0 0 1" type="slide" springref=".5" limited="true" stiffness="0.5" range="-0.024 0.0" damping="1"/>
        <geom pos="0.0 -0.00 0.0" size="0.01 0.01 0.005" type="box"/>
    </body>

    <body name="key_16" pos="0.23 -0.06 -0.05">
        <inertial pos="0.0 -0.0774 0.0" mass=".01" diaginertia="0.001 0.001 0.001"/>
        <joint name="key_joint_16" pos="0.0 0.0 0.0" axis="0 0 1" type="slide" springref=".5" limited="true" stiffness="0.5" range="-0.024 0.0" damping="1"/>
        <geom pos="0.0 -0.00 0.0" size="0.01 0.01 0.005" type="box"/>
    </body>

    <body name="key_17" pos="0.23 -0.09 -0.05">
        <inertial pos="0.0 -0.0774 0.0" mass=".01" diaginertia="0.001 0.001 0.001"/>
        <joint name="key_joint_17" pos="0.0 0.0 0.0" axis="0 0 1" type="slide" springref=".5" limited="true" stiffness="0.5" range="-0.024 0.0" damping="1"/>
        <geom pos="0.0 -0.00 0.0" size="0.01 0.01 0.005" type="box"/>
    </body>

    <body name="mp_0" pos="0.15 0.0 0.0">
        <inertial pos="0.0 -0.0774 0.0" mass=".01" diaginertia="0.001 0.001 0.001"/>
        <joint name="mp_0_joint_0" pos="0.0 0.0 0.0" axis="1 0 0" type="slide" springref=".0" limited="true" stiffness="0.5" range="-0.0 0.1" damping="1"/>
        <joint name="mp_0_joint_1" pos="0.0 0.0 0.0" axis="0 1 0" type="slide" springref=".0" limited="true" stiffness="0.5" range="-0.12 0.1" damping="1"/>
        <joint name="mp_0_joint_2" pos="0.0 0.0 0.0" axis="0 0 1" type="slide" springref=".0" limited="true" stiffness="0.5" range="-0.06 0.0" damping="1"/>
        <geom rgba="0 0 0 1" pos="0.0 -0.00 0.0" size="0.01 0.01 0.005" type="sphere"/>
        <site name="mp_0_tip" pos="0 0 0.0255" group="4"/>
    </body>

    <body name="mp_1" pos="0.15 0.0 0.0">
        <inertial pos="0.0 -0.0774 0.0" mass=".01" diaginertia="0.001 0.001 0.001"/>
        <joint name="mp_1_joint_0" pos="0.0 0.0 0.0" axis="1 0 0" type="slide" springref=".0" limited="true" stiffness="0.5" range="-0.0 0.1" damping="1"/>
        <joint name="mp_1_joint_1" pos="0.0 0.0 0.0" axis="0 1 0" type="slide" springref=".0" limited="true" stiffness="0.5" range="-0.12 0.1" damping="1"/>
        <joint name="mp_1_joint_2" pos="0.0 0.0 0.0" axis="0 0 1" type="slide" springref=".0" limited="true" stiffness="0.5" range="-0.06 0.0" damping="1"/>
        <geom rgba="1 1 1 1" pos="0.0 -0.00 0.0" size="0.01 0.01 0.005" type="sphere"/>
        <site name="mp_1_tip" pos="0 0 0.0255" group="4"/>
    </body>

  </worldbody>

  <sensor>
    <!-- hand. -->
    <framepos name="mp_0_tip_position" objtype="site" objname="mp_0_tip"/>
    <framepos name="mp_1_tip_position" objtype="site" objname="mp_1_tip"/>

    <!-- goal. -->
    <!-- <framepos name="goal_position" objtype="body" objname="goal_1"/> -->
  </sensor>

  <actuator>
    <position kp="5" kv="2" name="mp_0_joint_0_a" joint="mp_0_joint_0" ctrlrange="-0.05 0.1"/>
    <position kp="5" kv="2" name="mp_0_joint_1_a" joint="mp_0_joint_1" ctrlrange="-0.12 0.1"/>
    <position kp="5" kv="2" name="mp_0_joint_2_a" joint="mp_0_joint_2" ctrlrange="-0.2 0.0"/>

    <position kp="5" kv="1" name="mp_1_joint_0_a" joint="mp_1_joint_0" ctrlrange="-0.05 0.1"/>
    <position kp="5" kv="1" name="mp_1_joint_1_a" joint="mp_1_joint_1" ctrlrange="-0.12 0.1"/>
    <position kp="5" kv="1" name="mp_1_joint_2_a" joint="mp_1_joint_2" ctrlrange="-0.2 0.0"/>
  </actuator>

  <contact>
    <exclude body1="key_0" body2="key_1"/>
    <exclude body1="key_0" body2="key_2"/>
    <exclude body1="key_0" body2="key_3"/>
    <exclude body1="key_0" body2="key_4"/>
    <exclude body1="key_0" body2="key_5"/>
    <exclude body1="key_0" body2="key_6"/>
    <exclude body1="key_0" body2="key_7"/>

    <exclude body1="key_1" body2="key_2"/>
    <exclude body1="key_1" body2="key_3"/>
    <exclude body1="key_1" body2="key_4"/>
    <exclude body1="key_1" body2="key_5"/>
    <exclude body1="key_1" body2="key_6"/>
    <exclude body1="key_1" body2="key_7"/>

    <exclude body1="key_2" body2="key_3"/>
    <exclude body1="key_2" body2="key_4"/>
    <exclude body1="key_2" body2="key_5"/>
    <exclude body1="key_2" body2="key_6"/>
    <exclude body1="key_2" body2="key_7"/>

    <exclude body1="key_3" body2="key_4"/>
    <exclude body1="key_3" body2="key_5"/>
    <exclude body1="key_3" body2="key_6"/>
    <exclude body1="key_3" body2="key_7"/>

    <exclude body1="key_4" body2="key_5"/>
    <exclude body1="key_4" body2="key_6"/>
    <exclude body1="key_4" body2="key_7"/>

    <exclude body1="key_5" body2="key_6"/>
    <exclude body1="key_5" body2="key_7"/>

    <exclude body1="key_6" body2="key_7"/>
  </contact>

  <!-- <keyframe>
    <key name="home"
      qpos="
      0.3 0 0.8 0.8
      0.8 0 0.8 0.8
      0.8 0 0.8 0.8
      0.8 0.8 0.8 0
      0.8 0.8 0.8 0
      0.1 0.0 0.05 0.810967 -0.00262895 -0.585086 -0.000254303"
      ctrl="
      0.8 0 0.8 0.8
      0.8 0 0.8 0.8
      0.8 0 0.8 0.8
      0.8 0 0.8 0.8
      0.8 0.8 0.8 0" mpos="0.25 0.16 0"
      mquat="1 0 0 0"/>
  </keyframe> -->

  <keyframe>
    <key name="home"
      qpos="0 -0.1 0 0 0 0"
      ctrl="0 -0.1 0 0 0 0"/>
  </keyframe>
  <!-- <keyframe>
    <key name="home"
      qpos="
      0.5 -1.5 0.2 0.2
      0. 0.4 0.2 0.4
      0. 0.4 0.2 0.4
      0. 0.4 0.2 0.4
      0.4 0.3 0.4 0.9
      0.1 0.0 0.05 0.810967 -0.00262895 -0.585086 -0.000254303"
      ctrl="
      0.5 -1.5 0.2 0.2
      0. 0.4 0.2 0.4
      0. 0.4 0.2 0.4
      0. 0.4 0.2 0.4
      0.4 0.3 0.4 0.9" mpos="0.25 0.16 0"
      mquat="1 0 0 0"/>
  </keyframe> -->
</mujoco>
